<mujoco model="mini3">
  <default>
    <default class="robot">
      <default class="motor">
        <joint />
        <motor />
      </default>
      <default class="visual">
        <geom material="visualgeom" contype="0" conaffinity="0" group="2" />
      </default>
      <default class="collision">
        <geom material="collision_material" condim="3" contype="0" conaffinity="1" priority="1" group="1" solref="0.005 1" solimp="0.99 0.999 1e-05" friction="1 0.01 0.01" />
      </default>
    </default>
  </default>

  <compiler angle="radian" />

  <asset>
    <material name="default_material" rgba="0.7 0.7 0.7 1" />
    <material name="collision_material" rgba="1.0 0.28 0.1 0.3" />
    <mesh name="base_link.STL" file="../meshes/base_link.STL" />
    <mesh name="right_hip_pitch_link.STL" file="../meshes/right_hip_pitch_link.STL" />
    <mesh name="right_hip_roll_link.STL" file="../meshes/right_hip_roll_link.STL" />
    <mesh name="right_hip_yaw_link.STL" file="../meshes/right_hip_yaw_link.STL" />
    <mesh name="right_knee_pitch_link.STL" file="../meshes/right_knee_pitch_link.STL" />
    <mesh name="right_ankle_pitch_link.STL" file="../meshes/right_ankle_pitch_link.STL" />
    <mesh name="right_ankle_roll_link.STL" file="../meshes/right_ankle_roll_link.STL" />
    <mesh name="left_hip_pitch_link.STL" file="../meshes/left_hip_pitch_link.STL" />
    <mesh name="left_hip_roll_link.STL" file="../meshes/left_hip_roll_link.STL" />
    <mesh name="left_hip_yaw_link.STL" file="../meshes/left_hip_yaw_link.STL" />
    <mesh name="left_knee_pitch_link.STL" file="../meshes/left_knee_pitch_link.STL" />
    <mesh name="left_ankle_pitch_link.STL" file="../meshes/left_ankle_pitch_link.STL" />
    <mesh name="left_ankle_roll_link.STL" file="../meshes/left_ankle_roll_link.STL" />
    <mesh name="imu_link.STL" file="../meshes/imu_link.STL" />
    <mesh name="waist_yaw_link.STL" file="../meshes/waist_yaw_link.STL" />
    <mesh name="head_link.STL" file="../meshes/head_link.STL" />
    <mesh name="right_shoulder_pitch_link.STL" file="../meshes/right_shoulder_pitch_link.STL" />
    <mesh name="right_shoulder_roll_link.STL" file="../meshes/right_shoulder_roll_link.STL" />
    <mesh name="right_shoulder_yaw_link.STL" file="../meshes/right_shoulder_yaw_link.STL" />
    <mesh name="right_elbow_pitch_link.STL" file="../meshes/right_elbow_pitch_link.STL" />
    <mesh name="left_shoulder_pitch_link.STL" file="../meshes/left_shoulder_pitch_link.STL" />
    <mesh name="left_shoulder_roll_link.STL" file="../meshes/left_shoulder_roll_link.STL" />
    <mesh name="left_shoulder_yaw_link.STL" file="../meshes/left_shoulder_yaw_link.STL" />
    <mesh name="left_elbow_pitch_link.STL" file="../meshes/left_elbow_pitch_link.STL" />
  </asset>

  <worldbody>
    <body name="base_link" pos="0.00000000 0.00000000 0.42804900" quat="1 0 0 0" childclass="robot">
      <freejoint name="floating_base" />
      <geom name="base_link_collision" pos="0.003 0 0.007" quat="1.0 0.0 0.0 0.0" type="box" size="0.0375 0.065 0.035" class="collision" />
      <geom name="base_link_visual" pos="0 0 0" quat="1.0 0.0 0.0 0.0" material="" type="mesh" mesh="base_link.STL" class="visual" />
      <body name="right_hip_pitch_link" pos="0 -0.063 0" quat="1.0 0.0 0.0 0.0">
        <joint name="right_hip_pitch_joint"  ref="0.0" class="motor" range="-2.7925 2.7925" axis="0 1 0" armature="0.1244" />
        <inertial pos="-0.00283721676072844 -0.00116007970923913 -0.060111969278001" quat="1.0 0.0 0.0 0.0" mass="0.45534083" diaginertia="0.00029909 0.00029613 0.00018448" />
        <geom name="right_hip_pitch_link_visual" pos="0 0 0" quat="1.0 0.0 0.0 0.0" material="" type="mesh" mesh="right_hip_pitch_link.STL" class="visual" />
        <body name="right_hip_roll_link" pos="0.017301 0.002 -0.071497" quat="1.0 0.0 0.0 0.0">
          <joint name="right_hip_roll_joint"  ref="0.0" class="motor" range="-1.3963 1.5708" axis="1 0 0" armature="0.032" />
          <inertial pos="-0.00974448183575312 -3.13571384618558E-05 -0.0549610548515504" quat="1.0 0.0 0.0 0.0" mass="0.43533503" diaginertia="0.00027251 0.00028158 0.00018594" />
          <geom name="right_hip_roll_link_collision" pos="-0.018 0 -0.028" quat="1.0 0.0 0.0 0.0" type="box" size="0.0325 0.0275 0.053" class="collision" />
          <geom name="right_hip_roll_link_visual" pos="0 0 0" quat="1.0 0.0 0.0 0.0" material="" type="mesh" mesh="right_hip_roll_link.STL" class="visual" />
          <body name="right_hip_yaw_link" pos="-0.0173 0 -0.08905" quat="1.0 0.0 0.0 0.0">
            <joint name="right_hip_yaw_joint"  ref="0.0" class="motor" range="-2.7925 2.7925" axis="0 0 1" armature="0.032" />
            <inertial pos="-0.00668290598293377 0.00974076874837159 -0.0389139273354703" quat="1.0 0.0 0.0 0.0" mass="0.69608923" diaginertia="0.00042139 0.00046117 0.00039563" />
            <geom name="right_hip_yaw_link_collision" pos="-0.008 0.004 -0.04" quat="1.0 0.0 0.0 0.0" type="box" size="0.0325 0.04 0.03" class="collision" />
            <geom name="right_hip_yaw_link_visual" pos="0 0 0" quat="1.0 0.0 0.0 0.0" material="" type="mesh" mesh="right_hip_yaw_link.STL" class="visual" />
            <body name="right_knee_pitch_link" pos="-0.0080025 -0.01755 -0.043998" quat="1.0 0.0 0.0 0.0">
              <joint name="right_knee_pitch_joint"  ref="0.0" class="motor" range="-0.1 2.0944" axis="0 1 0" armature="0.1244" />
              <inertial pos="0.00392823767091797 0.0136119787091283 -0.0998531276401826" quat="1.0 0.0 0.0 0.0" mass="0.86819929 " diaginertia="0.00168401 0.00162304 0.00039688" />
              <geom name="right_knee_pitch_link_collision" pos="0.005 0.015 -0.125" quat="1.0 0.0 0.0 0.0" type="box" size="0.03 0.03 0.08" class="collision" />
              <geom name="right_knee_pitch_link_visual" pos="0 0 0" quat="1.0 0.0 0.0 0.0" material="" type="mesh" mesh="right_knee_pitch_link.STL" class="visual" />
              <body name="right_ankle_pitch_link" pos="0.0040029 0.01575 -0.2" quat="1.0 0.0 0.0 0.0">
                <joint name="right_ankle_pitch_joint"  ref="0.0" class="motor" range="-0.5236 0.5236" axis="0 1 0" armature="0.0019" />
                <inertial pos="-0.00196000504182704 -0.000155786952332537 -3.11490483406729E-09" quat="1.0 0.0 0.0 0.0" mass="0.03939937" diaginertia="1.49e-06 4.87e-06 4.38e-06" />
                <geom name="right_ankle_pitch_link_visual" pos="0 0 0" quat="1.0 0.0 0.0 0.0" material="" type="mesh" mesh="right_ankle_pitch_link.STL" class="visual" />
                <body name="right_ankle_roll_link" pos="0.0205 0 0" quat="1.0 0.0 0.0 0.0">
                  <joint name="right_ankle_roll_joint"  ref="0.0" class="motor" range="-0.2618 0.2618" axis="1 0 0" armature="0.0019" />
                  <inertial pos="-0.00940377293573548 0.000124519364271589 -0.0112390536944368" quat="1.0 0.0 0.0 0.0" mass="0.09936463" diaginertia="2.041e-05 0.00010785 0.00010645" />
                  <geom name="right_ankle_roll_link_collision" pos="0.006 0 -0.02" quat="1.0 0.0 0.0 0.0" type="box" size="0.065 0.025 0.0035" class="collision" />
                  <geom name="right_ankle_roll_link_visual" pos="0 0 0" quat="1.0 0.0 0.0 0.0" material="" type="mesh" mesh="right_ankle_roll_link.STL" class="visual" />
                </body>
              </body>
            </body>
          </body>
        </body>
      </body>
      <body name="left_hip_pitch_link" pos="0 0.063 0" quat="1.0 0.0 0.0 0.0">
        <joint name="left_hip_pitch_joint"  ref="0.0" class="motor" range="-2.7925 2.7925" axis="0 1 0" armature="0.1244" />
        <inertial pos="-0.00283442790197362 0.00112179369737812 -0.0600509563011839" quat="1.0 0.0 0.0 0.0" mass="0.45533636" diaginertia="0.00029872 0.0002953 0.00018495" />
        <geom name="left_hip_pitch_link_visual" pos="0 0 0" quat="1.0 0.0 0.0 0.0" material="" type="mesh" mesh="left_hip_pitch_link.STL" class="visual" />
        <body name="left_hip_roll_link" pos="0.017303 -0.002 -0.071501" quat="1.0 0.0 0.0 0.0">
          <joint name="left_hip_roll_joint"  ref="0.0" class="motor" range="-1.5708 1.3693" axis="1 0 0" armature="0.032" />
          <inertial pos="-0.00969635473882549 -7.94930952905601E-05 -0.0549610547750649" quat="1.0 0.0 0.0 0.0" mass="0.43533503" diaginertia="0.00027308 0.00028082 0.00018574" />
          <geom name="left_hip_roll_link_collision" pos="-0.018 0 -0.028" quat="1.0 0.0 0.0 0.0" type="box" size="0.0325 0.0275 0.053" class="collision" />
          <geom name="left_hip_roll_link_visual" pos="0 0 0" quat="1.0 0.0 0.0 0.0" material="" type="mesh" mesh="left_hip_roll_link.STL" class="visual" />
          <body name="left_hip_yaw_link" pos="-0.0173 0 -0.08905" quat="1.0 0.0 0.0 0.0">
            <joint name="left_hip_yaw_joint"  ref="0.0" class="motor" range="-2.7925 2.7925" axis="0 0 1" armature="0.032" />
            <inertial pos="-0.0067378311368791 -0.00974082453737066 -0.038914070589659" quat="1.0 0.0 0.0 0.0" mass="0.69608850" diaginertia="0.00042139 0.00046121 0.00039568" />
            <geom name="left_hip_yaw_link_collision" pos="-0.008 -0.004 -0.04" quat="1.0 0.0 0.0 0.0" type="box" size="0.0325 0.04 0.03" class="collision" />
            <geom name="left_hip_yaw_link_visual" pos="0 0 0" quat="1.0 0.0 0.0 0.0" material="" type="mesh" mesh="left_hip_yaw_link.STL" class="visual" />
            <body name="left_knee_pitch_link" pos="-0.0079974 0.01755 -0.043998" quat="1.0 0.0 0.0 0.0">
              <joint name="left_knee_pitch_joint"  ref="0.0" class="motor" range="-0.1 2.0944" axis="0 1 0" armature="0.1244" />
              <inertial pos="0.00392313559225752 -0.0135909738304269 -0.099888945253257" quat="1.0 0.0 0.0 0.0" mass="0.86819835" diaginertia="0.00168175 0.00162183 0.00039583" />
              <geom name="left_knee_pitch_link_collision" pos="0.005 -0.015 -0.125" quat="1.0 0.0 0.0 0.0" type="box" size="0.03 0.03 0.08" class="collision" />
              <geom name="left_knee_pitch_link_visual" pos="0 0 0" quat="1.0 0.0 0.0 0.0" material="" type="mesh" mesh="left_knee_pitch_link.STL" class="visual" />
              <body name="left_ankle_pitch_link" pos="0.0039977 -0.01575 -0.2" quat="1.0 0.0 0.0 0.0">
                <joint name="left_ankle_pitch_joint"  ref="0.0" class="motor" range="-0.5236 0.5236" axis="0 1 0" armature="0.0019" />
                <inertial pos="-0.00196000504182704 -0.000155786952332509 -3.11490472304499E-09" quat="1.0 0.0 0.0 0.0" mass="0.03939937 " diaginertia="1.49e-06 4.87e-06 4.38e-06" />
                <geom name="left_ankle_pitch_link_visual" pos="0 0 0" quat="1.0 0.0 0.0 0.0" material="" type="mesh" mesh="left_ankle_pitch_link.STL" class="visual" />
                <body name="left_ankle_roll_link" pos="0.0205 0 0" quat="1.0 0.0 0.0 0.0">
                  <joint name="left_ankle_roll_joint"  ref="0.0" class="motor" range="-0.2618 0.2618" axis="1 0 0" armature="0.0019" />
                  <inertial pos="-0.00940377293573549 0.000124519364271602 -0.011239053694437" quat="1.0 0.0 0.0 0.0" mass="0.09936463" diaginertia="2.041e-05 0.00010785 0.00010645" />
                  <geom name="left_ankle_roll_link_collision" pos="0.006 0 -0.02" quat="1.0 0.0 0.0 0.0" type="box" size="0.065 0.025 0.0035" class="collision" />
                  <geom name="left_ankle_roll_link_visual" pos="0 0 0" quat="1.0 0.0 0.0 0.0" material="" type="mesh" mesh="left_ankle_roll_link.STL" class="visual" />
                </body>
              </body>
            </body>
          </body>
        </body>
      </body>
      <body name="imu_link" pos="0.019 0 0.0555" quat="1.0 0.0 0.0 0.0">
        <inertial pos="0 8.97693584480558E-19 1.38777878078145E-17" quat="1.0 0.0 0.0 0.0" mass="0.01470000" diaginertia="2.27e-06 1.04e-06 1.78e-06" />
        <geom name="imu_link_visual" pos="0 0 0" quat="1.0 0.0 0.0 0.0" material="" type="mesh" mesh="imu_link.STL" class="visual" />
      </body>
      <body name="waist_yaw_link" pos="-0.022 0 0.051" quat="1.0 0.0 0.0 0.0">
        <joint name="waist_yaw_joint"  ref="0.0" class="motor" range="-2.7053 2.7053" axis="0 0 1" armature="0.032" />
        <inertial pos="0.00913761039407002 -0.000560703671928954 0.133423297418687" quat="1.0 0.0 0.0 0.0" mass="3.25904165" diaginertia="0.01741324 0.01608756 0.0053645" />
        <geom name="waist_yaw_link_collision" pos="0.005 0 0.135" quat="1.0 0.0 0.0 0.0" type="box" size="0.05 0.05 0.09" class="collision" />
        <geom name="waist_yaw_link_visual" pos="0 0 0" quat="1.0 0.0 0.0 0.0" material="" type="mesh" mesh="waist_yaw_link.STL" class="visual" />
        <body name="head_link" pos="0.0215 0 0.23445" quat="1.0 0.0 0.0 0.0">
          <inertial pos="-1.29250989241406E-07 7.01042276746148E-19 0.0813291604071748" quat="1.0 0.0 0.0 0.0" mass="0.12647901" diaginertia="0.00025148 0.00025148 0.00017738" />
          <geom name="head_link_visual" pos="0 0 0" quat="1.0 0.0 0.0 0.0" material="" type="mesh" mesh="head_link.STL" class="visual" />
        </body>
        <body name="right_shoulder_pitch_link" pos="-0.0044971 -0.06505 0.20704" quat="1.0 0.0 0.0 0.0">
          <joint name="right_shoulder_pitch_joint"  ref="0.0" class="motor" range="-3.6652 1.5708" axis="0 1 0" armature="0.0019" />
          <inertial pos="0.000553780540657526 -0.0311237578111765 6.73372750942258E-06" quat="1.0 0.0 0.0 0.0" mass="0.33783225" diaginertia="0.00015734 0.00013259 0.00014406" />
          <geom name="right_shoulder_pitch_link_collision" pos="0 -0.035 0.00" quat="1.0 0.0 0.0 0.0" type="box" size="0.03 0.03 0.03" class="collision" />
          <geom name="right_shoulder_pitch_link_visual" pos="0 0 0" quat="1.0 0.0 0.0 0.0" material="" type="mesh" mesh="right_shoulder_pitch_link.STL" class="visual" />
          <body name="right_shoulder_roll_link" pos="0.020497 -0.034993 0" quat="1.0 0.0 0.0 0.0">
            <joint name="right_shoulder_roll_joint"  ref="0.0" class="motor" range="-3.1416 0.09" axis="1 0 0" armature="0.0019" />
            <inertial pos="-0.00326855633416224 -7.01191449098415E-06 -0.0214507291947076" quat="1.0 0.0 0.0 0.0" mass="0.04472849" diaginertia="2.335e-05 2.425e-05 1.535e-05" />
            <geom name="right_shoulder_roll_link_visual" pos="0 0 0" quat="1.0 0.0 0.0 0.0" material="" type="mesh" mesh="right_shoulder_roll_link.STL" class="visual" />
            <body name="right_shoulder_yaw_link" pos="-0.020497 0 -0.041498" quat="1.0 0.0 0.0 0.0">
              <joint name="right_shoulder_yaw_joint"  ref="0.0" class="motor" range="-1.5708 1.5708" axis="0 0 1" armature="0.0019" />
              <inertial pos="3.52607129436994E-05 0.000596075048945696 -0.0836277402835895" quat="1.0 0.0 0.0 0.0" mass="0.65256770" diaginertia="0.00216193 0.0021725 0.00026354" />
              <geom name="right_shoulder_yaw_link_collision" pos="0 0 -0.06" quat="1.0 0.0 0.0 0.0" type="box" size="0.025 0.025 0.05" class="collision" />
              <geom name="right_shoulder_yaw_link_visual" pos="0 0 0" quat="1.0 0.0 0.0 0.0" material="" type="mesh" mesh="right_shoulder_yaw_link.STL" class="visual" />
              <body name="right_elbow_pitch_link" pos="0 -0.018507 -0.13405" quat="1.0 0.0 0.0 0.0">
                <joint name="right_elbow_pitch_joint"  ref="0.0" class="motor" range="-0.7854 3.927" axis="0 1 0" armature="0.0019" />
                <inertial pos="0.0461277851574696 0.00673806211577584 0.0019734708376653" quat="1.0 0.0 0.0 0.0" mass="0.07705194" diaginertia="2.671e-05 0.00012739 0.00013231" />
                <geom name="right_elbow_pitch_link_collision" pos="0.08 0.015 0" quat="1.0 0.0 0.0 0.0" type="box" size="0.065 0.025 0.02" class="collision" />
                <geom name="right_elbow_pitch_link_visual" pos="0 0 0" quat="1.0 0.0 0.0 0.0" material="" type="mesh" mesh="right_elbow_pitch_link.STL" class="visual" />
              </body>
            </body>
          </body>
        </body>
        <body name="left_shoulder_pitch_link" pos="-0.004507 0.06505 0.20705" quat="1.0 0.0 0.0 0.0">
          <joint name="left_shoulder_pitch_joint"  ref="0.0" class="motor" range="-3.6652 1.5708" axis="0 1 0" armature="0.0019" />
          <inertial pos="0.000563696900934673 0.0309849843017802 -3.15983504051154E-06" quat="1.0 0.0 0.0 0.0" mass="0.33783225" diaginertia="0.00015715 0.00013259 0.00014387" />
          <geom name="left_shoulder_pitch_link_collision" pos="0 0.035 0.00" quat="1.0 0.0 0.0 0.0" type="box" size="0.03 0.03 0.03" class="collision" />
          <geom name="left_shoulder_pitch_link_visual" pos="0 0 0" quat="1.0 0.0 0.0 0.0" material="" type="mesh" mesh="left_shoulder_pitch_link.STL" class="visual" />
          <body name="left_shoulder_roll_link" pos="0.020507 0.035007 0" quat="1.0 0.0 0.0 0.0">
            <joint name="left_shoulder_roll_joint"  ref="0.0" class="motor" range="-0.09 3.1416" axis="1 0 0" armature="0.0019" />
            <inertial pos="-0.00326855633416226 -7.01191452101568E-06 -0.0214507291947913" quat="1.0 0.0 0.0 0.0" mass="0.04472849" diaginertia="2.335e-05 2.425e-05 1.535e-05" />
            <geom name="left_shoulder_roll_link_visual" pos="0 0 0" quat="1.0 0.0 0.0 0.0" material="" type="mesh" mesh="left_shoulder_roll_link.STL" class="visual" />
            <body name="left_shoulder_yaw_link" pos="-0.020497 0 -0.041498" quat="1.0 0.0 0.0 0.0">
              <joint name="left_shoulder_yaw_joint"  ref="0.0" class="motor" range="-1.5708 1.5708" axis="0 0 1" armature="0.0019" />
              <inertial pos="-4.0168881263989E-05 -0.000685371483357941 -0.0836277403378965" quat="1.0 0.0 0.0 0.0" mass="0.65256770 " diaginertia="0.00216174 0.0021725 0.00026336" />
              <geom name="left_shoulder_yaw_link_collision" pos="0 0 -0.06" quat="1.0 0.0 0.0 0.0" type="box" size="0.025 0.025 0.05" class="collision" />
              <geom name="left_shoulder_yaw_link_visual" pos="0 0 0" quat="1.0 0.0 0.0 0.0" material="" type="mesh" mesh="left_shoulder_yaw_link.STL" class="visual" />
              <body name="left_elbow_pitch_link" pos="0 0.018493 -0.13405" quat="1.0 0.0 0.0 0.0">
                <joint name="left_elbow_pitch_joint"  ref="0.0" class="motor" range="-0.7854 3.927" axis="0 1 0" armature="0.0019" />
                <inertial pos="0.0500765470571522 -0.00724225033349378 0.00217149489910597" quat="1.0 0.0 0.0 0.0" mass="0.06667608" diaginertia="2.328e-05 0.00010943 0.00011365" />
                <geom name="left_elbow_pitch_link_collision" pos="0.08 -0.015 0" quat="1.0 0.0 0.0 0.0" type="box" size="0.065 0.025 0.02" class="collision" />
                <geom name="left_elbow_pitch_link_visual" pos="0 0 0" quat="1.0 0.0 0.0 0.0" material="" type="mesh" mesh="left_elbow_pitch_link.STL" class="visual" />
              </body>
            </body>
          </body>
        </body>
      </body>
      <site name="base_link_site" pos="0 0 0" quat="1 0 0 0" />
      <camera name="front_camera" mode="track" fovy="90.0" quat="4.329780281177467e-17 4.329780281177466e-17 0.7071067811865475 0.7071067811865476" pos="0.0 2.0 0.5" />
      <camera name="side_camera" mode="track" fovy="90.0" quat="-0.5 -0.4999999999999999 0.5 0.5000000000000001" pos="-2.0 0.0 0.5" />
    </body>
  </worldbody>

  <actuator>
    <motor name="right_hip_pitch_joint_ctrl" joint="right_hip_pitch_joint" class="motor" />
    <motor name="right_hip_roll_joint_ctrl" joint="right_hip_roll_joint" class="motor" />
    <motor name="right_hip_yaw_joint_ctrl" joint="right_hip_yaw_joint" class="motor" />
    <motor name="right_knee_pitch_joint_ctrl" joint="right_knee_pitch_joint" class="motor" />
    <motor name="right_ankle_pitch_joint_ctrl" joint="right_ankle_pitch_joint" class="motor" />
    <motor name="right_ankle_roll_joint_ctrl" joint="right_ankle_roll_joint" class="motor" />
    <motor name="left_hip_pitch_joint_ctrl" joint="left_hip_pitch_joint" class="motor" />
    <motor name="left_hip_roll_joint_ctrl" joint="left_hip_roll_joint" class="motor" />
    <motor name="left_hip_yaw_joint_ctrl" joint="left_hip_yaw_joint" class="motor" />
    <motor name="left_knee_pitch_joint_ctrl" joint="left_knee_pitch_joint" class="motor" />
    <motor name="left_ankle_pitch_joint_ctrl" joint="left_ankle_pitch_joint" class="motor" />
    <motor name="left_ankle_roll_joint_ctrl" joint="left_ankle_roll_joint" class="motor" />
    <motor name="waist_yaw_joint_ctrl" joint="waist_yaw_joint" class="motor" />
    <motor name="right_shoulder_pitch_joint_ctrl" joint="right_shoulder_pitch_joint" class="motor" />
    <motor name="right_shoulder_roll_joint_ctrl" joint="right_shoulder_roll_joint" class="motor" />
    <motor name="right_shoulder_yaw_joint_ctrl" joint="right_shoulder_yaw_joint" class="motor" />
    <motor name="right_elbow_pitch_joint_ctrl" joint="right_elbow_pitch_joint" class="motor" />
    <motor name="left_shoulder_pitch_joint_ctrl" joint="left_shoulder_pitch_joint" class="motor" />
    <motor name="left_shoulder_roll_joint_ctrl" joint="left_shoulder_roll_joint" class="motor" />
    <motor name="left_shoulder_yaw_joint_ctrl" joint="left_shoulder_yaw_joint" class="motor" />
    <motor name="left_elbow_pitch_joint_ctrl" joint="left_elbow_pitch_joint" class="motor" />
  </actuator>

  <contact>
    <exclude body1="base_link" body2="right_hip_pitch_link" />
    <exclude body1="base_link" body2="left_hip_pitch_link" />
    <exclude body1="base_link" body2="waist_yaw_link" />

    <!-- <exclude body1="waist_pitch_link" body2="waist_yaw_link" />

    <exclude body1="waist_pitch_link" body2="left_shoulder_yaw_link" />
    <exclude body1="waist_pitch_link" body2="right_shoulder_yaw_link" />
    <exclude body1="waist_pitch_link" body2="left_shoulder_roll_link" />
    <exclude body1="waist_pitch_link" body2="right_shoulder_roll_link" />
    <exclude body1="waist_pitch_link" body2="left_shoulder_pitch_link" />
    <exclude body1="waist_pitch_link" body2="right_shoulder_pitch_link" /> -->

    <exclude body1="right_knee_pitch_link" body2="right_ankle_pitch_link" />
    <exclude body1="right_knee_pitch_link" body2="right_ankle_roll_link" />

    <exclude body1="left_knee_pitch_link" body2="left_ankle_pitch_link" />
    <exclude body1="left_knee_pitch_link" body2="left_ankle_roll_link" />

    <exclude body1="right_ankle_roll_link" body2="right_ankle_pitch_link" />
    <exclude body1="left_ankle_roll_link" body2="left_ankle_pitch_link" />
  </contact>

  <sensor>
    <framepos name="base_link_site_pos" objtype="site" objname="base_link_site" />
    <framequat name="base_link_site_quat" objtype="site" objname="base_link_site" />
    <framelinvel name="base_link_site_linvel" objtype="site" objname="base_link_site" />
    <frameangvel name="base_link_site_angvel" objtype="site" objname="base_link_site" />
    <velocimeter name="base_link_site_vel" site="base_link_site" />
  </sensor>
</mujoco>
